<robot name="dumpUrdf">

  <link name="base" >
    <inertial>
      <origin rpy = "0 0 0" xyz = "0 0 0" />
      <mass value = "0.0001" />
      <inertia ixx = "0.0001" ixy = "0" ixz = "0" iyy = "0.0001" iyz = "0" izz = "0.0001" />
    </inertial>
  </link>

  <link name="root" >
    <inertial>
      <origin rpy = "0 0 0" xyz = "0.00 0.07 0.00" />
      <mass value = "6.000000" />
      <inertia ixx = "0.019440" ixy = "0" ixz = "0" iyy = "0.019440" iyz = "0" izz = "0.019440" />
    </inertial>
    <collision>
      <origin rpy = "0 0 0" xyz = "0.000000 0.070000 0.000000" />
      <geometry>
        <sphere radius = "0.090000" />
      </geometry>
    </collision>
  </link>

  <!-- joint between base and root -->
  <joint name="root" type="fixed" >
    <parent link = "base" />
    <child link="root" />
    <origin rpy = "0 0 0" xyz = "0.000000 0.000000 0.000000" />
  </joint>

  <link name="chest" >
    <inertial>
      <origin rpy = "0 0 0" xyz = "0.000000 0.120000 0.000000" />
      <mass value = "14.000000" />
      <inertia ixx = "0.067760" ixy = "0" ixz = "0" iyy = "0.067760" iyz = "0" izz = "0.067760" />
    </inertial>
    <collision>
      <origin rpy = "0 0 0" xyz = "0.000000 0.120000 0.000000" />
      <geometry>
        <sphere radius = "0.110000" />
      </geometry>
    </collision>
  </link>

  <!-- joint between root and chest -->
  <link name="root_chest_link_fixed">
  </link>
  <joint name="root_chest_joint_fixed" type="fixed">
    <origin rpy="0 0 0" xyz="0.000000 0.236151 0.000000"/>
    <parent link="root"/>
    <child link="root_chest_link_fixed"/>
  </joint>

  <link name="root_chest_link1">
  </link>
  <joint name="root_chest_joint1" type="revolute">
    <parent link="root_chest_link_fixed"/>
    <child link="root_chest_link1"/>
    <axis xyz="0 1 0"/>
    <limit effort="1000.0" lower="-6.28" upper="6.28" velocity="100"/>
  </joint>

  <link name="root_chest_link2">
  </link>
  <joint name="root_chest_joint2" type="revolute">
    <parent link="root_chest_link1"/>
    <child link="root_chest_link2"/>
    <axis xyz="0 0 1"/>
    <limit effort="1000.0" lower="-6.28" upper="6.28" velocity="100"/>
  </joint>

  <joint name="root_chest_joint3" type="revolute">
    <parent link="root_chest_link2"/>
    <child link="chest"/>
    <axis xyz="1 0 0"/>
    <limit effort="1000.0" lower="-6.28" upper="6.28" velocity="100"/>
  </joint>

  <link name="neck" >
    <inertial>
      <origin rpy = "0 0 0" xyz = "0.000000 0.175000 0.000000" />
      <mass value = "2.000000" />
      <inertia ixx = "0.008405" ixy = "0" ixz = "0" iyy = "0.008405" iyz = "0" izz = "0.008405" />
    </inertial>
    <collision>
      <origin rpy = "0 0 0" xyz = "0.000000 0.175000 0.000000" />
      <geometry>
        <sphere radius = "0.1025000" />
      </geometry>
    </collision>
  </link>

  <!-- joint between chest and neck -->
  <link name="chest_neck_link_fixed">
  </link>
  <joint name="chest_neck_joint_fixed" type="fixed">
    <origin rpy="0 0 0" xyz="0.000000 0.223894 0.000000"/>
    <parent link="chest"/>
    <child link="chest_neck_link_fixed"/>
  </joint>

  <link name="chest_neck_link1">
  </link>
  <joint name="chest_neck_joint1" type="revolute">
    <parent link="chest_neck_link_fixed"/>
    <child link="chest_neck_link1"/>
    <axis xyz="0 1 0"/>
    <limit effort="1000.0" lower="-6.28" upper="6.28" velocity="100"/>
  </joint>
  <link name="chest_neck_link2">
  </link>
  <joint name="chest_neck_joint2" type="revolute">
    <parent link="chest_neck_link1"/>
    <child link="chest_neck_link2"/>
    <axis xyz="0 0 1"/>
    <limit effort="1000.0" lower="-6.28" upper="6.28" velocity="100"/>
  </joint>
  <joint name="chest_neck_joint3" type="revolute">
    <parent link="chest_neck_link2"/>
    <child link="neck"/>
    <axis xyz="1 0 0"/>
    <limit effort="1000.0" lower="-6.28" upper="6.28" velocity="100"/>
  </joint>

  <link name="right_hip" >
    <inertial>
      <origin rpy = "0 0 0" xyz = "0.000000 -0.210000 0.000000" />
      <mass value = "4.500000" />
      <inertia ixx = "0.056282" ixy = "0" ixz = "0" iyy = "0.006539" iyz = "0" izz = "0.056282" />
    </inertial>
    <collision>
      <origin rpy = "-1.570796 0 0" xyz = "0.000000 -0.210000 0.000000" />
      <geometry>
        <capsule length="0.300000" radius="0.0550000"/>
      </geometry>
    </collision>
  </link>

  <!-- joint between root and right_hip -->
  <link name="root_right_hip_link_fixed">
  </link>
  <joint name="root_right_hip_joint_fixed" type="fixed">
    <origin rpy="0 0 0" xyz="0.000000 0.000000 0.084887"/>
    <parent link="root"/>
    <child link="root_right_hip_link_fixed"/>
  </joint>

  <link name="root_right_hip_link1">
  </link>
  <joint name="root_right_hip_joint1" type="revolute">
    <parent link="root_right_hip_link_fixed"/>
    <child link="root_right_hip_link1"/>
    <axis xyz="0 1 0"/>
    <limit effort="1000.0" lower="-6.28" upper="6.28" velocity="100"/>
  </joint>

  <link name="root_right_hip_link2">
  </link>
  <joint name="root_right_hip_joint2" type="revolute">
    <parent link="root_right_hip_link1"/>
    <child link="root_right_hip_link2"/>
    <axis xyz="0 0 1"/>
    <limit effort="1000.0" lower="-6.28" upper="6.28" velocity="100"/>
  </joint>

  <joint name="root_right_hip_joint3" type="revolute">
    <parent link="root_right_hip_link2"/>
    <child link="right_hip"/>
    <axis xyz="1 0 0"/>
    <limit effort="1000.0" lower="-6.28" upper="6.28" velocity="100"/>
  </joint>

  <link name="right_knee" >
    <inertial>
      <origin rpy = "0 0 0" xyz = "0.000000 -0.200000 0.000000" />
      <mass value = "3.000000" />
      <inertia ixx = "0.037690" ixy = "0" ixz = "0" iyy = "0.003617" iyz = "0" izz = "0.037690" />
    </inertial>
    <collision>
      <origin rpy = "-1.570796 0 0" xyz = "0.000000 -0.200000 0.000000" />
      <geometry>
        <capsule length="0.310000" radius="0.050000"/>
      </geometry>
    </collision>
  </link>

  <!-- joint between right_hip and right_knee -->
  <joint name="right_knee" type="revolute" >
    <parent link="right_hip" />
    <child link="right_knee" />
    <limit effort="1000.0" lower="-6.28" upper="0." velocity="0.5"/>
    <origin rpy = "0 0 0" xyz = "0.000000 -0.421546 0.000000" />
    <axis xyz = "0.000000 0.000000 1.000000" />
  </joint>

  <link name="right_ankle" >
    <inertial>
      <origin rpy = "0 0 0" xyz = "0.045000 -0.022500 0.000000" />
      <mass value = "1.000000" />
      <inertia ixx = "0.000927" ixy = "0" ixz = "0" iyy = "0.003286" iyz = "0" izz = "0.002863" />
    </inertial>
    <collision>
      <origin rpy = "0 0 0" xyz = "0.045000 -0.022500 0.000000" />
      <geometry>
        <box size="0.177000 0.055000 0.090000" />
      </geometry>
    </collision>
  </link>

  <!-- joint between right_knee and right_ankle -->
  <link name="right_knee_right_ankle_link_fixed">
  </link>
  <joint name="right_knee_right_ankle_joint_fixed" type="fixed">
    <origin rpy="0 0 0" xyz="0.000000 -0.409870 0.000000"/>
    <parent link="right_knee"/>
    <child link="right_knee_right_ankle_link_fixed"/>
  </joint>
  
  <link name="right_knee_right_ankle_link1">
  </link>
  <joint name="right_knee_right_ankle_joint1" type="revolute">
    <parent link="right_knee_right_ankle_link_fixed"/>
    <child link="right_knee_right_ankle_link1"/>
    <axis xyz="0 1 0"/>
    <limit effort="1000.0" lower="-6.28" upper="6.28" velocity="100"/>
  </joint>

  <link name="right_knee_right_ankle_link2">
  </link>
  <joint name="right_knee_right_ankle_joint2" type="revolute">
    <parent link="right_knee_right_ankle_link1"/>
    <child link="right_knee_right_ankle_link2"/>
    <axis xyz="0 0 1"/>
    <limit effort="1000.0" lower="-6.28" upper="6.28" velocity="100"/>
  </joint>

  <joint name="right_knee_right_ankle_joint3" type="revolute">
    <parent link="right_knee_right_ankle_link2"/>
    <child link="right_ankle"/>
    <axis xyz="1 0 0"/>
    <limit effort="1000.0" lower="-6.28" upper="6.28" velocity="100"/>
  </joint>



  <link name="right_shoulder" >
    <inertial>
      <origin rpy = "0 0 0" xyz = "0.000000 -0.140000 0.000000" />
      <mass value = "1.500000" />
      <inertia ixx = "0.008087" ixy = "0" ixz = "0" iyy = "0.001443" iyz = "0" izz = "0.008087" />
    </inertial>
    <collision>
      <origin rpy = "-1.570796 0 0" xyz = "0.000000 -0.140000 0.000000" />
      <geometry>
        <capsule length="0.180000" radius="0.045000"/>
      </geometry>
    </collision>
  </link>

  <!-- joint between chest and right_shoulder -->
  <link name="chest_right_shoulder_link_fixed">
  </link>
  <joint name="chest_right_shoulder_joint_fixed" type="fixed">
    <origin rpy="0 0 0" xyz="-0.02406 0.24350 0.18311"/>
    <parent link="chest"/>
    <child link="chest_right_shoulder_link_fixed"/>
  </joint>

  <link name="chest_right_shoulder_link1">
  </link>
  <joint name="chest_right_shoulder_joint1" type="revolute">
    <parent link="chest_right_shoulder_link_fixed"/>
    <child link="chest_right_shoulder_link1"/>
    <axis xyz="0 1 0"/>
    <limit effort="1000.0" lower="-6.28" upper="6.28" velocity="100"/>
  </joint>

  <link name="chest_right_shoulder_link2">
  </link>
  <joint name="chest_right_shoulder_joint2" type="revolute">
    <parent link="chest_right_shoulder_link1"/>
    <child link="chest_right_shoulder_link2"/>
    <axis xyz="0 0 1"/>
    <limit effort="1000.0" lower="-6.28" upper="6.28" velocity="100"/>
  </joint>
  <joint name="chest_right_shoulder_joint3" type="revolute">
    <parent link="chest_right_shoulder_link2"/>
    <child link="right_shoulder"/>
    <axis xyz="1 0 0"/>
    <limit eeffort="1000.0" lower="-6.28" upper="6.28" velocity="100"/>
  </joint>

  <link name="right_elbow" >
    <inertial>
      <origin rpy = "0 0 0" xyz = "0.000000 -0.120000 0.000000" />
      <mass value = "1.000000" />
      <inertia ixx = "0.003420" ixy = "0" ixz = "0" iyy = "0.000755" iyz = "0" izz = "0.003420" />
    </inertial>
    <collision>
      <origin rpy = "-1.570796 0 0" xyz = "0.000000 -0.120000 0.000000" />
      <geometry>
        <capsule length="0.135" radius="0.04"/>
      </geometry>
    </collision>
  </link>

  <joint name="right_elbow" type="revolute" >
    <parent link="right_shoulder" />
    <child link="right_elbow" />
    <limit effort="1000.0" lower="0" upper="6.28" velocity="0.5"/>
    <origin rpy = "0 0 0" xyz = "0.000000 -0.274788 0.000000" />
    <axis xyz = "0.000000 0.000000 1.000000" />
  </joint>

  <link name="right_wrist" >
    <inertial>
      <origin rpy = "0 0 0" xyz = "0.000000 0.000000 0.000000" />
      <mass value = "0.500000" />
      <inertia ixx = "0.000320" ixy = "0" ixz = "0" iyy = "0.000320" iyz = "0" izz = "0.000320" />
    </inertial>
    <collision>
      <origin rpy = "0 0 0" xyz = "0.000000 0.000000 0.000000" />
      <geometry>
        <sphere radius = "0.040000" />
      </geometry>
    </collision>
  </link>

  <joint name="right_wrist" type="fixed" >
    <parent link="right_elbow" />
    <child link="right_wrist" />
    <origin rpy = "0 0 0" xyz = "0.000000 -0.258947 0.000000" />
  </joint>

  <link name="left_hip" >
    <inertial>
      <origin rpy = "0 0 0" xyz = "0.000000 -0.210000 0.000000" />
      <mass value = "4.500000" />
      <inertia ixx = "0.056282" ixy = "0" ixz = "0" iyy = "0.006539" iyz = "0" izz = "0.056282" />
    </inertial>
    <collision>
        <origin rpy = "-1.570796 0 0" xyz = "0.000000 -0.210000 0.000000" />
      <geometry>
        <capsule length="0.300000" radius="0.055000"/>
      </geometry>
    </collision>
  </link>

  <link name="root_left_hip_link_fixed">
  </link>
  <joint name="root_left_hip_joint_fixed" type="fixed">
    <origin rpy="0 0 0" xyz="0.000000 0.000000 -0.084887"/>
    <parent link="root"/>
    <child link="root_left_hip_link_fixed"/>
  </joint>

  <link name="root_left_hip_link1">
  </link>
  <joint name="root_left_hip_joint1" type="revolute">
    <parent link="root_left_hip_link_fixed"/>
    <child link="root_left_hip_link1"/>
    <axis xyz="0 1 0"/>
    <limit effort="1000.0" lower="-6.28" upper="6.28" velocity="100"/>
  </joint>

  <link name="root_left_hip_link2">
  </link>
  <joint name="root_left_hip_joint2" type="revolute">
    <parent link="root_left_hip_link1"/>
    <child link="root_left_hip_link2"/>
    <axis xyz="0 0 1"/>
    <limit effort="1000.0" lower="-6.28" upper="6.28" velocity="100"/>
  </joint>

  <joint name="root_left_hip_joint3" type="revolute">
    <parent link="root_left_hip_link2"/>
    <child link="left_hip"/>
    <axis xyz="1 0 0"/>
    <limit effort="1000.0" lower="-6.28" upper="6.28" velocity="100"/>
  </joint>

  <link name="left_knee" >
    <inertial>
      <origin rpy = "0 0 0" xyz = "0.000000 -0.200000 0.000000" />
      <mass value = "3.000000" />
      <inertia ixx = "0.037690" ixy = "0" ixz = "0" iyy = "0.003617" iyz = "0" izz = "0.037690" />
    </inertial>
    <collision>
      <origin rpy = "-1.570796 0 0" xyz = "0.000000 -0.200000 0.000000" />
      <geometry>
        <capsule length="0.310000" radius="0.050000"/>
      </geometry>
    </collision>
  </link>

  <joint name="left_knee" type="revolute" >
    <parent link="left_hip" />
    <child link="left_knee" />
    <limit effort="1000.0" lower="-6.28" upper="0." velocity="0.5"/>
    <origin rpy = "0 0 0" xyz = "0.000000 -0.421546 0.000000" />
    <axis xyz = "0.000000 0.000000 1.000000" />
  </joint>

  <link name="left_ankle" >
    <inertial>
      <origin rpy = "0 0 0" xyz = "0.045000 -0.022500 0.000000" />
      <mass value = "1.000000" />
      <inertia ixx = "0.000927" ixy = "0" ixz = "0" iyy = "0.003286" iyz = "0" izz = "0.002863" />
    </inertial>
    <collision>
      <origin rpy = "0 0 0" xyz = "0.045000 -0.022500 0.000000" />
      <geometry>
        <box size="0.177000 0.055000 0.090000" />
      </geometry>
    </collision>
  </link>

  <link name="left_knee_left_ankle_link_fixed">
  </link>
  <joint name="left_knee_left_ankle_joint_fixed" type="fixed">
    <origin rpy="0 0 0" xyz="0.000000 -0.40987 0.000000"/>
    <parent link="left_knee"/>
    <child link="left_knee_left_ankle_link_fixed"/>
  </joint>
  
  <link name="left_knee_left_ankle_link1">
  </link>
  <joint name="left_knee_left_ankle_joint1" type="revolute">
    <parent link="left_knee_left_ankle_link_fixed"/>
    <child link="left_knee_left_ankle_link1"/>
    <axis xyz="0 1 0"/>
    <limit effort="1000.0" lower="-6.28" upper="6.28" velocity="100"/>
  </joint>

  <link name="left_knee_left_ankle_link2">
  </link>
  <joint name="left_knee_left_ankle_joint2" type="revolute">
    <parent link="left_knee_left_ankle_link1"/>
    <child link="left_knee_left_ankle_link2"/>
    <axis xyz="0 0 1"/>
    <limit effort="1000.0" lower="-6.28" upper="6.28" velocity="100"/>
  </joint>

  <joint name="left_knee_left_ankle_joint3" type="revolute">
    <parent link="left_knee_left_ankle_link2"/>
    <child link="left_ankle"/>
    <axis xyz="1 0 0"/>
    <limit effort="1000.0" lower="-6.28" upper="6.28" velocity="100"/>
  </joint>

  <link name="left_shoulder" >
    <inertial>
      <origin rpy = "0 0 0" xyz = "0.000000 -0.140000 0.000000" />
      <mass value = "1.500000" />
      <inertia ixx = "0.008087" ixy = "0" ixz = "0" iyy = "0.001443" iyz = "0" izz = "0.008087" />
    </inertial>
    <collision>
      <origin rpy = "-1.570796 0 0" xyz = "0.000000 -0.140000 0.000000" />
      <geometry>
        <capsule length="0.180000" radius="0.045000"/>
      </geometry>
    </collision>
  </link>

  <link name="chest_left_shoulder_link_fixed">
  </link>
  <joint name="chest_left_shoulder_joint_fixed" type="fixed">
    <origin rpy="0 0 0" xyz="-0.02405 0.24350 -0.18311"/>
    <parent link="chest"/>
    <child link="chest_left_shoulder_link_fixed"/>
  </joint>

  <link name="chest_left_shoulder_link1">
  </link>
  <joint name="chest_left_shoulder_joint1" type="revolute">
    <parent link="chest_left_shoulder_link_fixed"/>
    <child link="chest_left_shoulder_link1"/>
    <axis xyz="0 1 0"/>
    <limit effort="1000.0" lower="-6.28" upper="6.28" velocity="100"/>
  </joint>

  <link name="chest_left_shoulder_link2">
  </link>
  <joint name="chest_left_shoulder_joint2" type="revolute">
    <parent link="chest_left_shoulder_link1"/>
    <child link="chest_left_shoulder_link2"/>
    <axis xyz="0 0 1"/>
    <limit effort="1000.0" lower="-6.28" upper="6.28" velocity="100"/>
  </joint>
  <joint name="chest_left_shoulder_joint3" type="revolute">
    <parent link="chest_left_shoulder_link2"/>
    <child link="left_shoulder"/>
    <axis xyz="1 0 0"/>
    <limit effort="10000.0" lower="-6.28" upper="6.28" velocity="100"/>
  </joint>

  <link name="left_elbow" >
    <inertial>
      <origin rpy = "0 0 0" xyz = "0.000000 -0.120000 0.000000" />
      <mass value = "1.000000" />
      <inertia ixx = "0.003420" ixy = "0" ixz = "0" iyy = "0.000755" iyz = "0" izz = "0.003420" />
    </inertial>
    <collision>
      <origin rpy = "-1.570796 0 0" xyz = "0.000000 -0.120000 0.000000" />
      <geometry>
        <capsule length="0.135000" radius="0.040000"/>
      </geometry>
    </collision>
  </link>

  <joint name="left_elbow" type="revolute" >
    <parent link="left_shoulder" />
    <child link="left_elbow" />
    <limit effort="1000.0" lower="0" upper="6.28" velocity="0.5"/>
    <origin rpy = "0 0 0" xyz = "0.000000 -0.274788 0.000000" />
    <axis xyz = "0.000000 0.000000 1.000000" />
  </joint>

  <link name="left_wrist" >
    <inertial>
      <origin rpy = "0 0 0" xyz = "0.000000 0.000000 0.000000" />
      <mass value = "0.500000" />
      <inertia ixx = "0.000320" ixy = "0" ixz = "0" iyy = "0.000320" iyz = "0" izz = "0.000320" />
    </inertial>
    <collision>
      <origin rpy = "0 0 0" xyz = "0.000000 0.000000 0.000000" />
      <geometry>
        <sphere radius = "0.040000" />
      </geometry>
    </collision>
  </link>

  <joint name="left_wrist" type="fixed" >
    <parent link="left_elbow" />
    <child link="left_wrist" />
    <origin rpy = "0 0 0" xyz = "0.000000 -0.258947 0.000000" />
  </joint>

</robot>
